Workbook

Sheet Dashboard
A1: EMBASSY OUTREACH — LEADERSHIP DASHBOARD
A2: ="As of "&TEXT(Lists!K2,"dd mmm yyyy")&" | Source: Embassy Outreach Database ("&COUNTA(Outreach_Data!A2:A79)&" records) | NOTE: illustrative sample data — the real database was not supplied with the assessment" -> As of 06 Oct 2026 | Source: Embassy Outreach Database (78 records) | NOTE: illustrative sample data — the real database was not supplied with the assessment
A4: UNIQUE EMBASSIES | C4: OUTREACH COVERAGE | E4: ENGAGEMENT RATE | G4: ACTIVE PARTNERSHIPS | I4: OVERDUE FOLLOW-UPS | K4: STALE CONTACTS | M4: RECORDS WITH DATA ISSUES
A5: =SUMPRODUCT(1/COUNTIF(Outreach_Data!$B$2:$B$79,Outreach_Data!$B$2:$B$79)) -> 73 | C5: =SUM(Outreach_Data!$AB$2:$AB$79)/COUNTA(Outreach_Data!$A$2:$A$79) -> 0.83333333 | E5: =IF(SUM(Outreach_Data!$AB$2:$AB$79)=0,0,SUM(Outreach_Data!$AA$2:$AA$79)/SUM(Outreach_Data!$AB$2:$AB$79)) -> 0.46153846 | G5: =COUNTIF(Outreach_Data!$S$2:$S$79,"Partnership Active") -> 7 | I5: =SUM(Outreach_Data!$V$2:$V$79) -> 31 | K5: =SUM(Outreach_Data!$X$2:$X$79) -> 30 | M5: =COUNTIF(Outreach_Data!$Y$2:$Y$79,">0") -> 49
A6: =COUNTA(Outreach_Data!$A$2:$A$79)&" records incl. duplicates" -> 78 records incl. duplicates | C6: =SUM(Outreach_Data!$AB$2:$AB$79)&" of "&COUNTA(Outreach_Data!$A$2:$A$79)&" records contacted" -> 65 of 78 records contacted | E6: =SUM(Outreach_Data!$AA$2:$AA$79)&" of "&SUM(Outreach_Data!$AB$2:$AB$79)&" contacted are engaged" -> 30 of 65 contacted are engaged | G6: ="status: Partnership Active" -> status: Partnership Active | I6: =IF(SUM(Outreach_Data!$V$2:$V$79)=0,"none overdue","avg "&ROUND(AVERAGEIF(Outreach_Data!$V$2:$V$79,1,Outreach_Data!$W$2:$W$79),0)&" days late") -> avg 30 days late | K6: ="no touchpoint in "&Lists!$K$3&"+ days" -> no touchpoint in 30+ days | M6: =TEXT(COUNTIF(Outreach_Data!$Y$2:$Y$79,">0")/COUNTA(Outreach_Data!$A$2:$A$79),"0%")&" of records — see DQ sheet" -> 63% of records — see DQ sheet
A8: Pipeline by Status | E8: Regional Performance | M8: Engagement Level
A9: Status | B9: Records | C9: % of Total | E9: Region | F9: Records | G9: Contacted | H9: Engaged | I9: Active Partners | J9: Engagement Rate | K9: Overdue | M9: Level | N9: Records
A10: Not Started | B10: =COUNTIF(Outreach_Data!$S$2:$S$79,A10) -> 10 | C10: =B10/$B$18 -> 0.12820513 | E10: Europe | F10: =COUNTIF(Outreach_Data!$R$2:$R$79,E10) -> 21 | G10: =SUMIFS(Outreach_Data!$AB$2:$AB$79,Outreach_Data!$R$2:$R$79,E10) -> 19 | H10: =SUMIFS(Outreach_Data!$AA$2:$AA$79,Outreach_Data!$R$2:$R$79,E10) -> 7 | I10: =COUNTIFS(Outreach_Data!$R$2:$R$79,E10,Outreach_Data!$S$2:$S$79,"Partnership Active") -> 1 | J10: =IF(G10=0,0,H10/G10) -> 0.36842105 | K10: =SUMIFS(Outreach_Data!$V$2:$V$79,Outreach_Data!$R$2:$R$79,E10) -> 8 | M10: High | N10: =COUNTIF(Outreach_Data!$T$2:$T$79,M10) -> 12
A11: Contacted | B11: =COUNTIF(Outreach_Data!$S$2:$S$79,A11) -> 19 | C11: =B11/$B$18 -> 0.24358974 | E11: Asia-Pacific | F11: =COUNTIF(Outreach_Data!$R$2:$R$79,E11) -> 18 | G11: =SUMIFS(Outreach_Data!$AB$2:$AB$79,Outreach_Data!$R$2:$R$79,E11) -> 17 | H11: =SUMIFS(Outreach_Data!$AA$2:$AA$79,Outreach_Data!$R$2:$R$79,E11) -> 9 | I11: =COUNTIFS(Outreach_Data!$R$2:$R$79,E11,Outreach_Data!$S$2:$S$79,"Partnership Active") -> 3 | J11: =IF(G11=0,0,H11/G11) -> 0.52941176 | K11: =SUMIFS(Outreach_Data!$V$2:$V$79,Outreach_Data!$R$2:$R$79,E11) -> 8 | M11: Medium | N11: =COUNTIF(Outreach_Data!$T$2:$T$79,M11) -> 26
A12: No Response | B12: =COUNTIF(Outreach_Data!$S$2:$S$79,A12) -> 12 | C12: =B12/$B$18 -> 0.15384615 | E12: Middle East | F12: =COUNTIF(Outreach_Data!$R$2:$R$79,E12) -> 13 | G12: =SUMIFS(Outreach_Data!$AB$2:$AB$79,Outreach_Data!$R$2:$R$79,E12) -> 12 | H12: =SUMIFS(Outreach_Data!$AA$2:$AA$79,Outreach_Data!$R$2:$R$79,E12) -> 9 | I12: =COUNTIFS(Outreach_Data!$R$2:$R$79,E12,Outreach_Data!$S$2:$S$79,"Partnership Active") -> 3 | J12: =IF(G12=0,0,H12/G12) -> 0.75 | K12: =SUMIFS(Outreach_Data!$V$2:$V$79,Outreach_Data!$R$2:$R$79,E12) -> 5 | M12: Low | N12: =COUNTIF(Outreach_Data!$T$2:$T$79,M12) -> 19
A13: In Discussion | B13: =COUNTIF(Outreach_Data!$S$2:$S$79,A13) -> 14 | C13: =B13/$B$18 -> 0.17948718 | E13: Africa | F13: =COUNTIF(Outreach_Data!$R$2:$R$79,E13) -> 13 | G13: =SUMIFS(Outreach_Data!$AB$2:$AB$79,Outreach_Data!$R$2:$R$79,E13) -> 12 | H13: =SUMIFS(Outreach_Data!$AA$2:$AA$79,Outreach_Data!$R$2:$R$79,E13) -> 4 | I13: =COUNTIFS(Outreach_Data!$R$2:$R$79,E13,Outreach_Data!$S$2:$S$79,"Partnership Active") -> 0 | J13: =IF(G13=0,0,H13/G13) -> 0.33333333 | K13: =SUMIFS(Outreach_Data!$V$2:$V$79,Outreach_Data!$R$2:$R$79,E13) -> 6 | M13: None | N13: =COUNTIF(Outreach_Data!$T$2:$T$79,M13) -> 16
A14: Meeting Scheduled | B14: =COUNTIF(Outreach_Data!$S$2:$S$79,A14) -> 9 | C14: =B14/$B$18 -> 0.11538462 | E14: Americas | F14: =COUNTIF(Outreach_Data!$R$2:$R$79,E14) -> 10 | G14: =SUMIFS(Outreach_Data!$AB$2:$AB$79,Outreach_Data!$R$2:$R$79,E14) -> 4 | H14: =SUMIFS(Outreach_Data!$AA$2:$AA$79,Outreach_Data!$R$2:$R$79,E14) -> 0 | I14: =COUNTIFS(Outreach_Data!$R$2:$R$79,E14,Outreach_Data!$S$2:$S$79,"Partnership Active") -> 0 | J14: =IF(G14=0,0,H14/G14) -> 0 | K14: =SUMIFS(Outreach_Data!$V$2:$V$79,Outreach_Data!$R$2:$R$79,E14) -> 4 | M14: Not Recorded | N14: =COUNTIF(Outreach_Data!$T$2:$T$79,M14) -> 5
A15: Partnership Active | B15: =COUNTIF(Outreach_Data!$S$2:$S$79,A15) -> 7 | C15: =B15/$B$18 -> 0.08974359 | E15: Not Recorded | F15: =COUNTIF(Outreach_Data!$R$2:$R$79,E15) -> 3 | G15: =SUMIFS(Outreach_Data!$AB$2:$AB$79,Outreach_Data!$R$2:$R$79,E15) -> 1 | H15: =SUMIFS(Outreach_Data!$AA$2:$AA$79,Outreach_Data!$R$2:$R$79,E15) -> 1 | I15: =COUNTIFS(Outreach_Data!$R$2:$R$79,E15,Outreach_Data!$S$2:$S$79,"Partnership Active") -> 0 | J15: =IF(G15=0,0,H15/G15) -> 1 | K15: =SUMIFS(Outreach_Data!$V$2:$V$79,Outreach_Data!$R$2:$R$79,E15) -> 0 | M15: Total | N15: =SUM(N10:N14) -> 78
A16: On Hold | B16: =COUNTIF(Outreach_Data!$S$2:$S$79,A16) -> 4 | C16: =B16/$B$18 -> 0.051282051 | E16: Total | F16: =SUM(F10:F15) -> 78 | G16: =SUM(G10:G15) -> 65 | H16: =SUM(H10:H15) -> 30 | I16: =SUM(I10:I15) -> 7 | J16: =IF(G16=0,0,H16/G16) -> 0.46153846 | K16: =SUM(K10:K15) -> 31
A17: Not Recorded | B17: =COUNTIF(Outreach_Data!$S$2:$S$79,A17) -> 3 | C17: =B17/$B$18 -> 0.038461538
A18: Total | B18: =SUM(B10:B17) -> 78 | C18: =SUM(C10:C17) -> 1
A36: Last Contact by Month | K36: Owner Workload
A37: Month | B37: Embassies | K37: Owner | L37: Records | M37: Engaged | N37: Overdue
A38: Jan 26 | B38: =COUNTIFS(Outreach_Data!$K$2:$K$79,">="&DATE(2026,1,1),Outreach_Data!$K$2:$K$79,"<"&DATE(2026,2,1)) -> 0 | K38: Aisha Khan | L38: =COUNTIF(Outreach_Data!$I$2:$I$79,K38) -> 13 | M38: =SUMIFS(Outreach_Data!$AA$2:$AA$79,Outreach_Data!$I$2:$I$79,K38) -> 4 | N38: =SUMIFS(Outreach_Data!$V$2:$V$79,Outreach_Data!$I$2:$I$79,K38) -> 4
A39: Feb 26 | B39: =COUNTIFS(Outreach_Data!$K$2:$K$79,">="&DATE(2026,2,1),Outreach_Data!$K$2:$K$79,"<"&DATE(2026,3,1)) -> 0 | K39: Rohan Mehta | L39: =COUNTIF(Outreach_Data!$I$2:$I$79,K39) -> 13 | M39: =SUMIFS(Outreach_Data!$AA$2:$AA$79,Outreach_Data!$I$2:$I$79,K39) -> 3 | N39: =SUMIFS(Outreach_Data!$V$2:$V$79,Outreach_Data!$I$2:$I$79,K39) -> 4
A40: Mar 26 | B40: =COUNTIFS(Outreach_Data!$K$2:$K$79,">="&DATE(2026,3,1),Outreach_Data!$K$2:$K$79,"<"&DATE(2026,4,1)) -> 0 | K40: Priya Nair | L40: =COUNTIF(Outreach_Data!$I$2:$I$79,K40) -> 8 | M40: =SUMIFS(Outreach_Data!$AA$2:$AA$79,Outreach_Data!$I$2:$I$79,K40) -> 4 | N40: =SUMIFS(Outreach_Data!$V$2:$V$79,Outreach_Data!$I$2:$I$79,K40) -> 3
A41: Apr 26 | B41: =COUNTIFS(Outreach_Data!$K$2:$K$79,">="&DATE(2026,4,1),Outreach_Data!$K$2:$K$79,"<"&DATE(2026,5,1)) -> 2 | K41: Imran Sheikh | L41: =COUNTIF(Outreach_Data!$I$2:$I$79,K41) -> 11 | M41: =SUMIFS(Outreach_Data!$AA$2:$AA$79,Outreach_Data!$I$2:$I$79,K41) -> 5 | N41: =SUMIFS(Outreach_Data!$V$2:$V$79,Outreach_Data!$I$2:$I$79,K41) -> 4
A42: May 26 | B42: =COUNTIFS(Outreach_Data!$K$2:$K$79,">="&DATE(2026,5,1),Outreach_Data!$K$2:$K$79,"<"&DATE(2026,6,1)) -> 1 | K42: Neha Verma | L42: =COUNTIF(Outreach_Data!$I$2:$I$79,K42) -> 17 | M42: =SUMIFS(Outreach_Data!$AA$2:$AA$79,Outreach_Data!$I$2:$I$79,K42) -> 8 | N42: =SUMIFS(Outreach_Data!$V$2:$V$79,Outreach_Data!$I$2:$I$79,K42) -> 9
A43: Jun 26 | B43: =COUNTIFS(Outreach_Data!$K$2:$K$79,">="&DATE(2026,6,1),Outreach_Data!$K$2:$K$79,"<"&DATE(2026,7,1)) -> 4 | K43: Karan Joshi | L43: =COUNTIF(Outreach_Data!$I$2:$I$79,K43) -> 9 | M43: =SUMIFS(Outreach_Data!$AA$2:$AA$79,Outreach_Data!$I$2:$I$79,K43) -> 3 | N43: =SUMIFS(Outreach_Data!$V$2:$V$79,Outreach_Data!$I$2:$I$79,K43) -> 4
A44: Jul 26 | B44: =COUNTIFS(Outreach_Data!$K$2:$K$79,">="&DATE(2026,7,1),Outreach_Data!$K$2:$K$79,"<"&DATE(2026,8,1)) -> 6 | K44: Unassigned | L44: =SUMPRODUCT(--(Outreach_Data!$I$2:$I$79="")) -> 7 | M44: =SUMPRODUCT((Outreach_Data!$I$2:$I$79="")*Outreach_Data!$AA$2:$AA$79) -> 3 | N44: =SUMPRODUCT((Outreach_Data!$I$2:$I$79="")*Outreach_Data!$V$2:$V$79) -> 3
A45: Aug 26 | B45: =COUNTIFS(Outreach_Data!$K$2:$K$79,">="&DATE(2026,8,1),Outreach_Data!$K$2:$K$79,"<"&DATE(2026,9,1)) -> 18 | K45: Total | L45: =SUM(L38:L44) -> 78 | M45: =SUM(M38:M44) -> 30 | N45: =SUM(N38:N44) -> 31
A46: Sep 26 | B46: =COUNTIFS(Outreach_Data!$K$2:$K$79,">="&DATE(2026,9,1),Outreach_Data!$K$2:$K$79,"<"&DATE(2026,10,1)) -> 26
A47: Oct 26 | B47: =COUNTIFS(Outreach_Data!$K$2:$K$79,">="&DATE(2026,10,1),Outreach_Data!$K$2:$K$79,"<"&DATE(2026,11,1)) -> 4
A50: Priority Attention List — Top 10 Overdue Follow-ups (ranked by days overdue)
A51: Embassy | B51: Region | C51: Status | E51: Owner | G51: Days Overdue | H51: Next Action | L51: Contact Person | P51: helper: data row index
A52: =IF($P52="","",IF(INDEX(Outreach_Data!$B$2:$B$79,$P52)="","—",INDEX(Outreach_Data!$B$2:$B$79,$P52))) -> Oman | B52: =IF($P52="","",IF(INDEX(Outreach_Data!$R$2:$R$79,$P52)="","—",INDEX(Outreach_Data!$R$2:$R$79,$P52))) -> Middle East | C52: =IF($P52="","",IF(INDEX(Outreach_Data!$S$2:$S$79,$P52)="","—",INDEX(Outreach_Data!$S$2:$S$79,$P52))) -> No Response | E52: =IF($P52="","",IF(INDEX(Outreach_Data!$I$2:$I$79,$P52)="","—",INDEX(Outreach_Data!$I$2:$I$79,$P52))) -> Imran Sheikh | G52: =IF($P52="","",IF(INDEX(Outreach_Data!$W$2:$W$79,$P52)="","—",INDEX(Outreach_Data!$W$2:$W$79,$P52))) -> 93 | H52: =IF($P52="","",IF(INDEX(Outreach_Data!$O$2:$O$79,$P52)="","—",INDEX(Outreach_Data!$O$2:$O$79,$P52))) -> Escalate via phone / alternate contact | L52: =IF($P52="","",IF(INDEX(Outreach_Data!$D$2:$D$79,$P52)="","—",INDEX(Outreach_Data!$D$2:$D$79,$P52))) -> — | P52: =IFERROR(IF(LARGE(Outreach_Data!$Z$2:$Z$79,1)>0,MATCH(LARGE(Outreach_Data!$Z$2:$Z$79,1),Outreach_Data!$Z$2:$Z$79,0),""),"") -> 68
A53: =IF($P53="","",IF(INDEX(Outreach_Data!$B$2:$B$79,$P53)="","—",INDEX(Outreach_Data!$B$2:$B$79,$P53))) -> Guyana | B53: =IF($P53="","",IF(INDEX(Outreach_Data!$R$2:$R$79,$P53)="","—",INDEX(Outreach_Data!$R$2:$R$79,$P53))) -> Americas | C53: =IF($P53="","",IF(INDEX(Outreach_Data!$S$2:$S$79,$P53)="","—",INDEX(Outreach_Data!$S$2:$S$79,$P53))) -> No Response | E53: =IF($P53="","",IF(INDEX(Outreach_Data!$I$2:$I$79,$P53)="","—",INDEX(Outreach_Data!$I$2:$I$79,$P53))) -> Priya Nair | G53: =IF($P53="","",IF(INDEX(Outreach_Data!$W$2:$W$79,$P53)="","—",INDEX(Outreach_Data!$W$2:$W$79,$P53))) -> 79 | H53: =IF($P53="","",IF(INDEX(Outreach_Data!$O$2:$O$79,$P53)="","—",INDEX(Outreach_Data!$O$2:$O$79,$P53))) -> Escalate via phone / alternate contact | L53: =IF($P53="","",IF(INDEX(Outreach_Data!$D$2:$D$79,$P53)="","—",INDEX(Outreach_Data!$D$2:$D$79,$P53))) -> Yusuf Chen | P53: =IFERROR(IF(LARGE(Outreach_Data!$Z$2:$Z$79,2)>0,MATCH(LARGE(Outreach_Data!$Z$2:$Z$79,2),Outreach_Data!$Z$2:$Z$79,0),""),"") -> 25
A54: =IF($P54="","",IF(INDEX(Outreach_Data!$B$2:$B$79,$P54)="","—",INDEX(Outreach_Data!$B$2:$B$79,$P54))) -> Finland | B54: =IF($P54="","",IF(INDEX(Outreach_Data!$R$2:$R$79,$P54)="","—",INDEX(Outreach_Data!$R$2:$R$79,$P54))) -> Europe | C54: =IF($P54="","",IF(INDEX(Outreach_Data!$S$2:$S$79,$P54)="","—",INDEX(Outreach_Data!$S$2:$S$79,$P54))) -> No Response | E54: =IF($P54="","",IF(INDEX(Outreach_Data!$I$2:$I$79,$P54)="","—",INDEX(Outreach_Data!$I$2:$I$79,$P54))) -> Imran Sheikh | G54: =IF($P54="","",IF(INDEX(Outreach_Data!$W$2:$W$79,$P54)="","—",INDEX(Outreach_Data!$W$2:$W$79,$P54))) -> 72 | H54: =IF($P54="","",IF(INDEX(Outreach_Data!$O$2:$O$79,$P54)="","—",INDEX(Outreach_Data!$O$2:$O$79,$P54))) -> Escalate via phone / alternate contact | L54: =IF($P54="","",IF(INDEX(Outreach_Data!$D$2:$D$79,$P54)="","—",INDEX(Outreach_Data!$D$2:$D$79,$P54))) -> David Fernandez | P54: =IFERROR(IF(LARGE(Outreach_Data!$Z$2:$Z$79,3)>0,MATCH(LARGE(Outreach_Data!$Z$2:$Z$79,3),Outreach_Data!$Z$2:$Z$79,0),""),"") -> 67
A55: =IF($P55="","",IF(INDEX(Outreach_Data!$B$2:$B$79,$P55)="","—",INDEX(Outreach_Data!$B$2:$B$79,$P55))) -> South Korea | B55: =IF($P55="","",IF(INDEX(Outreach_Data!$R$2:$R$79,$P55)="","—",INDEX(Outreach_Data!$R$2:$R$79,$P55))) -> Asia-Pacific | C55: =IF($P55="","",IF(INDEX(Outreach_Data!$S$2:$S$79,$P55)="","—",INDEX(Outreach_Data!$S$2:$S$79,$P55))) -> No Response | E55: =IF($P55="","",IF(INDEX(Outreach_Data!$I$2:$I$79,$P55)="","—",INDEX(Outreach_Data!$I$2:$I$79,$P55))) -> Rohan Mehta | G55: =IF($P55="","",IF(INDEX(Outreach_Data!$W$2:$W$79,$P55)="","—",INDEX(Outreach_Data!$W$2:$W$79,$P55))) -> 70 | H55: =IF($P55="","",IF(INDEX(Outreach_Data!$O$2:$O$79,$P55)="","—",INDEX(Outreach_Data!$O$2:$O$79,$P55))) -> Escalate via phone / alternate contact | L55: =IF($P55="","",IF(INDEX(Outreach_Data!$D$2:$D$79,$P55)="","—",INDEX(Outreach_Data!$D$2:$D$79,$P55))) -> Kwame Fernandez | P55: =IFERROR(IF(LARGE(Outreach_Data!$Z$2:$Z$79,4)>0,MATCH(LARGE(Outreach_Data!$Z$2:$Z$79,4),Outreach_Data!$Z$2:$Z$79,0),""),"") -> 10
A56: =IF($P56="","",IF(INDEX(Outreach_Data!$B$2:$B$79,$P56)="","—",INDEX(Outreach_Data!$B$2:$B$79,$P56))) -> Uganda | B56: =IF($P56="","",IF(INDEX(Outreach_Data!$R$2:$R$79,$P56)="","—",INDEX(Outreach_Data!$R$2:$R$79,$P56))) -> Africa | C56: =IF($P56="","",IF(INDEX(Outreach_Data!$S$2:$S$79,$P56)="","—",INDEX(Outreach_Data!$S$2:$S$79,$P56))) -> No Response | E56: =IF($P56="","",IF(INDEX(Outreach_Data!$I$2:$I$79,$P56)="","—",INDEX(Outreach_Data!$I$2:$I$79,$P56))) -> Aisha Khan | G56: =IF($P56="","",IF(INDEX(Outreach_Data!$W$2:$W$79,$P56)="","—",INDEX(Outreach_Data!$W$2:$W$79,$P56))) -> 66 | H56: =IF($P56="","",IF(INDEX(Outreach_Data!$O$2:$O$79,$P56)="","—",INDEX(Outreach_Data!$O$2:$O$79,$P56))) -> Escalate via phone / alternate contact | L56: =IF($P56="","",IF(INDEX(Outreach_Data!$D$2:$D$79,$P56)="","—",INDEX(Outreach_Data!$D$2:$D$79,$P56))) -> Layla Ali | P56: =IFERROR(IF(LARGE(Outreach_Data!$Z$2:$Z$79,5)>0,MATCH(LARGE(Outreach_Data!$Z$2:$Z$79,5),Outreach_Data!$Z$2:$Z$79,0),""),"") -> 72
A57: =IF($P57="","",IF(INDEX(Outreach_Data!$B$2:$B$79,$P57)="","—",INDEX(Outreach_Data!$B$2:$B$79,$P57))) -> Ghana | B57: =IF($P57="","",IF(INDEX(Outreach_Data!$R$2:$R$79,$P57)="","—",INDEX(Outreach_Data!$R$2:$R$79,$P57))) -> Africa | C57: =IF($P57="","",IF(INDEX(Outreach_Data!$S$2:$S$79,$P57)="","—",INDEX(Outreach_Data!$S$2:$S$79,$P57))) -> No Response | E57: =IF($P57="","",IF(INDEX(Outreach_Data!$I$2:$I$79,$P57)="","—",INDEX(Outreach_Data!$I$2:$I$79,$P57))) -> Imran Sheikh | G57: =IF($P57="","",IF(INDEX(Outreach_Data!$W$2:$W$79,$P57)="","—",INDEX(Outreach_Data!$W$2:$W$79,$P57))) -> 66 | H57: =IF($P57="","",IF(INDEX(Outreach_Data!$O$2:$O$79,$P57)="","—",INDEX(Outreach_Data!$O$2:$O$79,$P57))) -> Escalate via phone / alternate contact | L57: =IF($P57="","",IF(INDEX(Outreach_Data!$D$2:$D$79,$P57)="","—",INDEX(Outreach_Data!$D$2:$D$79,$P57))) -> Kwame Kowalski | P57: =IFERROR(IF(LARGE(Outreach_Data!$Z$2:$Z$79,6)>0,MATCH(LARGE(Outreach_Data!$Z$2:$Z$79,6),Outreach_Data!$Z$2:$Z$79,0),""),"") -> 44
A58: =IF($P58="","",IF(INDEX(Outreach_Data!$B$2:$B$79,$P58)="","—",INDEX(Outreach_Data!$B$2:$B$79,$P58))) -> Indonesia | B58: =IF($P58="","",IF(INDEX(Outreach_Data!$R$2:$R$79,$P58)="","—",INDEX(Outreach_Data!$R$2:$R$79,$P58))) -> Asia-Pacific | C58: =IF($P58="","",IF(INDEX(Outreach_Data!$S$2:$S$79,$P58)="","—",INDEX(Outreach_Data!$S$2:$S$79,$P58))) -> No Response | E58: =IF($P58="","",IF(INDEX(Outreach_Data!$I$2:$I$79,$P58)="","—",INDEX(Outreach_Data!$I$2:$I$79,$P58))) -> Karan Joshi | G58: =IF($P58="","",IF(INDEX(Outreach_Data!$W$2:$W$79,$P58)="","—",INDEX(Outreach_Data!$W$2:$W$79,$P58))) -> 61 | H58: =IF($P58="","",IF(INDEX(Outreach_Data!$O$2:$O$79,$P58)="","—",INDEX(Outreach_Data!$O$2:$O$79,$P58))) -> Escalate via phone / alternate contact | L58: =IF($P58="","",IF(INDEX(Outreach_Data!$D$2:$D$79,$P58)="","—",INDEX(Outreach_Data!$D$2:$D$79,$P58))) -> — | P58: =IFERROR(IF(LARGE(Outreach_Data!$Z$2:$Z$79,7)>0,MATCH(LARGE(Outreach_Data!$Z$2:$Z$79,7),Outreach_Data!$Z$2:$Z$79,0),""),"") -> 2
A59: =IF($P59="","",IF(INDEX(Outreach_Data!$B$2:$B$79,$P59)="","—",INDEX(Outreach_Data!$B$2:$B$79,$P59))) -> South Africa | B59: =IF($P59="","",IF(INDEX(Outreach_Data!$R$2:$R$79,$P59)="","—",INDEX(Outreach_Data!$R$2:$R$79,$P59))) -> Africa | C59: =IF($P59="","",IF(INDEX(Outreach_Data!$S$2:$S$79,$P59)="","—",INDEX(Outreach_Data!$S$2:$S$79,$P59))) -> Contacted | E59: =IF($P59="","",IF(INDEX(Outreach_Data!$I$2:$I$79,$P59)="","—",INDEX(Outreach_Data!$I$2:$I$79,$P59))) -> Priya Nair | G59: =IF($P59="","",IF(INDEX(Outreach_Data!$W$2:$W$79,$P59)="","—",INDEX(Outreach_Data!$W$2:$W$79,$P59))) -> 42 | H59: =IF($P59="","",IF(INDEX(Outreach_Data!$O$2:$O$79,$P59)="","—",INDEX(Outreach_Data!$O$2:$O$79,$P59))) -> Follow-up email | L59: =IF($P59="","",IF(INDEX(Outreach_Data!$D$2:$D$79,$P59)="","—",INDEX(Outreach_Data!$D$2:$D$79,$P59))) -> Liam Ali | P59: =IFERROR(IF(LARGE(Outreach_Data!$Z$2:$Z$79,8)>0,MATCH(LARGE(Outreach_Data!$Z$2:$Z$79,8),Outreach_Data!$Z$2:$Z$79,0),""),"") -> 19
A60: =IF($P60="","",IF(INDEX(Outreach_Data!$B$2:$B$79,$P60)="","—",INDEX(Outreach_Data!$B$2:$B$79,$P60))) -> Malaysia | B60: =IF($P60="","",IF(INDEX(Outreach_Data!$R$2:$R$79,$P60)="","—",INDEX(Outreach_Data!$R$2:$R$79,$P60))) -> Asia-Pacific | C60: =IF($P60="","",IF(INDEX(Outreach_Data!$S$2:$S$79,$P60)="","—",INDEX(Outreach_Data!$S$2:$S$79,$P60))) -> No Response | E60: =IF($P60="","",IF(INDEX(Outreach_Data!$I$2:$I$79,$P60)="","—",INDEX(Outreach_Data!$I$2:$I$79,$P60))) -> Neha Verma | G60: =IF($P60="","",IF(INDEX(Outreach_Data!$W$2:$W$79,$P60)="","—",INDEX(Outreach_Data!$W$2:$W$79,$P60))) -> 42 | H60: =IF($P60="","",IF(INDEX(Outreach_Data!$O$2:$O$79,$P60)="","—",INDEX(Outreach_Data!$O$2:$O$79,$P60))) -> Escalate via phone / alternate contact | L60: =IF($P60="","",IF(INDEX(Outreach_Data!$D$2:$D$79,$P60)="","—",INDEX(Outreach_Data!$D$2:$D$79,$P60))) -> Liam Rossi | P60: =IFERROR(IF(LARGE(Outreach_Data!$Z$2:$Z$79,9)>0,MATCH(LARGE(Outreach_Data!$Z$2:$Z$79,9),Outreach_Data!$Z$2:$Z$79,0),""),"") -> 15
A61: =IF($P61="","",IF(INDEX(Outreach_Data!$B$2:$B$79,$P61)="","—",INDEX(Outreach_Data!$B$2:$B$79,$P61))) -> Bahrain | B61: =IF($P61="","",IF(INDEX(Outreach_Data!$R$2:$R$79,$P61)="","—",INDEX(Outreach_Data!$R$2:$R$79,$P61))) -> Middle East | C61: =IF($P61="","",IF(INDEX(Outreach_Data!$S$2:$S$79,$P61)="","—",INDEX(Outreach_Data!$S$2:$S$79,$P61))) -> No Response | E61: =IF($P61="","",IF(INDEX(Outreach_Data!$I$2:$I$79,$P61)="","—",INDEX(Outreach_Data!$I$2:$I$79,$P61))) -> Neha Verma | G61: =IF($P61="","",IF(INDEX(Outreach_Data!$W$2:$W$79,$P61)="","—",INDEX(Outreach_Data!$W$2:$W$79,$P61))) -> 37 | H61: =IF($P61="","",IF(INDEX(Outreach_Data!$O$2:$O$79,$P61)="","—",INDEX(Outreach_Data!$O$2:$O$79,$P61))) -> Escalate via phone / alternate contact | L61: =IF($P61="","",IF(INDEX(Outreach_Data!$D$2:$D$79,$P61)="","—",INDEX(Outreach_Data!$D$2:$D$79,$P61))) -> Mina Ali | P61: =IFERROR(IF(LARGE(Outreach_Data!$Z$2:$Z$79,10)>0,MATCH(LARGE(Outreach_Data!$Z$2:$Z$79,10),Outreach_Data!$Z$2:$Z$79,0),""),"") -> 28
...

Sheet Data Quality Review
A1: DATA QUALITY REVIEW — EMBASSY OUTREACH DATABASE
A2: ="Counts are live formulas on the Outreach_Data sheet ("&COUNTA(Outreach_Data!$A$2:$A$79)&" records, as of "&TEXT(Lists!K2,"dd mmm yyyy")&"). Severity reflects impact on leadership reporting." -> Counts are live formulas on the Outreach_Data sheet (78 records, as of 06 Oct 2026). Severity reflects impact on leadership reporting.
A4: # | B4: Check | C4: Field(s) | D4: Records Affected | E4: % of Records | F4: Severity | G4: Impact on reporting / decisions | H4: Recommended fix
A5: 1 | B5: Duplicate embassy entries | C5: Embassy (Country) | D5: =SUMPRODUCT(--(COUNTIF(Outreach_Data!$B$2:$B$79,Outreach_Data!$B$2:$B$79)>1)) -> 10 | E5: =D5/COUNTA(Outreach_Data!$A$2:$A$79) -> 0.12820513 | F5: High | G5: Same embassy appears under more than one ID with different owners/contacts; inflates counts and splits history. | H5: Merge duplicates; enforce one primary record per embassy with multiple contacts in a child table.
A6: 2 | B6: Status not recorded | C6: Status | D6: =COUNTBLANK(Outreach_Data!$L$2:$L$79) -> 3 | E6: =D6/COUNTA(Outreach_Data!$A$2:$A$79) -> 0.038461538 | F6: High | G6: Record cannot be placed in the pipeline; understates progress. | H6: Make Status mandatory (dropdown).
A7: 3 | B7: Non-standard status labels | C7: Status | D7: =SUMPRODUCT((Outreach_Data!$L$2:$L$79<>"")*(1-EXACT(Outreach_Data!$L$2:$L$79,Outreach_Data!$S$2:$S$79))) -> 12 | E7: =D7/COUNTA(Outreach_Data!$A$2:$A$79) -> 0.15384615 | F7: Medium | G7: Case/spacing/abbreviation variants (e.g. 'Active', 'in discussion') break pivots and filters unless cleaned. | H7: Replace free text with a controlled dropdown list.
A8: 4 | B8: Region missing | C8: Region | D8: =COUNTBLANK(Outreach_Data!$C$2:$C$79) -> 3 | E8: =D8/COUNTA(Outreach_Data!$A$2:$A$79) -> 0.038461538 | F8: High | G8: Regional engagement cannot be monitored for these embassies. | H8: Derive region from country via lookup table.
A9: 5 | B9: Non-standard region labels | C9: Region | D9: =SUMPRODUCT((Outreach_Data!$C$2:$C$79<>"")*(1-EXACT(Outreach_Data!$C$2:$C$79,Outreach_Data!$R$2:$R$79))) -> 9 | E9: =D9/COUNTA(Outreach_Data!$A$2:$A$79) -> 0.11538462 | F9: Medium | G9: Variants such as 'APAC' and 'Asia Pacific' split one region into several. | H9: Standardise to five regions via lookup.
A10: 6 | B10: Engagement level missing | C10: Engagement Level | D10: =COUNTBLANK(Outreach_Data!$M$2:$M$79) -> 5 | E10: =D10/COUNTA(Outreach_Data!$A$2:$A$79) -> 0.064102564 | F10: Medium | G10: Engagement mix is understated. | H10: Define scoring rules (interactions, recency) and auto-calculate.
A11: 7 | B11: Non-standard engagement labels | C11: Engagement Level | D11: =SUMPRODUCT((Outreach_Data!$M$2:$M$79<>"")*(1-EXACT(Outreach_Data!$M$2:$M$79,Outreach_Data!$T$2:$T$79))) -> 8 | E11: =D11/COUNTA(Outreach_Data!$A$2:$A$79) -> 0.1025641 | F11: Low | G11: Inconsistent capitalisation / abbreviations ('Med', 'Nil'). | H11: Dropdown list.
A12: 8 | B12: No owner assigned | C12: Owner | D12: =COUNTBLANK(Outreach_Data!$I$2:$I$79) -> 7 | E12: =D12/COUNTA(Outreach_Data!$A$2:$A$79) -> 0.08974359 | F12: High | G12: No accountability for follow-up; invisible in owner workload. | H12: Assign an owner to every record; review weekly.
A13: 9 | B13: Contact person missing | C13: Contact Person | D13: =COUNTBLANK(Outreach_Data!$D$2:$D$79) -> 3 | E13: =D13/COUNTA(Outreach_Data!$A$2:$A$79) -> 0.038461538 | F13: Medium | G13: Outreach cannot be personalised; hard to hand over. | H13: Capture at least one named contact.
A14: 10 | B14: Email missing | C14: Email | D14: =COUNTBLANK(Outreach_Data!$F$2:$F$79) -> 6 | E14: =D14/COUNTA(Outreach_Data!$A$2:$A$79) -> 0.076923077 | F14: Medium | G14: Embassy cannot be reached by email. | H14: Source from official embassy sites.
A15: 11 | B15: Invalid email format (no '@') | C15: Email | D15: =SUMPRODUCT(--(Outreach_Data!$F$2:$F$79<>""),--ISERROR(FIND("@",Outreach_Data!$F$2:$F$79))) -> 4 | E15: =D15/COUNTA(Outreach_Data!$A$2:$A$79) -> 0.051282051 | F15: Medium | G15: Emails will bounce. | H15: Add format validation at entry.
A16: 12 | B16: Phone missing | C16: Phone | D16: =COUNTBLANK(Outreach_Data!$G$2:$G$79) -> 6 | E16: =D16/COUNTA(Outreach_Data!$A$2:$A$79) -> 0.076923077 | F16: Low | G16: Phone escalation not possible. | H16: Capture from official sources.
A17: 13 | B17: Phone not in +country format | C17: Phone | D17: =SUMPRODUCT((Outreach_Data!$G$2:$G$79<>"")*(LEFT(Outreach_Data!$G$2:$G$79,1)<>"+")) -> 9 | E17: =D17/COUNTA(Outreach_Data!$A$2:$A$79) -> 0.11538462 | F17: Low | G17: Inconsistent formats hinder dialling and de-duplication. | H17: Standardise to international format.
A18: 14 | B18: Dates stored as text | C18: First / Last Contact, Next Action Due | D18: =SUMPRODUCT(--((ISTEXT(Outreach_Data!$J$2:$J$79)+ISTEXT(Outreach_Data!$K$2:$K$79)+ISTEXT(Outreach_Data!$P$2:$P$79))>0)) -> 5 | E18: =D18/COUNTA(Outreach_Data!$A$2:$A$79) -> 0.064102564 | F18: High | G18: Text dates are ignored by date formulas — recency, overdue and monthly trend are understated. | H18: Convert to true dates; restrict the column to date entry.
A19: 15 | B19: Last contact earlier than first contact | C19: First / Last Contact | D19: =SUMPRODUCT(ISNUMBER(Outreach_Data!$J$2:$J$79)*ISNUMBER(Outreach_Data!$K$2:$K$79)*(Outreach_Data!$K$2:$K$79<Outreach_Data!$J$2:$J$79)) -> 4 | E19: =D19/COUNTA(Outreach_Data!$A$2:$A$79) -> 0.051282051 | F19: High | G19: Logically impossible; distorts engagement history. | H19: Correct dates; add validation (Last ≥ First).
A20: 16 | B20: Last contact date in the future | C20: Last Contact Date | D20: =COUNTIF(Outreach_Data!$K$2:$K$79,">"&Lists!$K$2) -> 2 | E20: =D20/COUNTA(Outreach_Data!$A$2:$A$79) -> 0.025641026 | F20: High | G20: Probably typos; hides stale records. | H20: Validate against today's date.
A21: 17 | B21: Outreach started but no contact date | C21: Last Contact Date vs Status | D21: =SUMPRODUCT((Outreach_Data!$S$2:$S$79<>"Not Started")*(Outreach_Data!$S$2:$S$79<>"Not Recorded")*(Outreach_Data!$K$2:$K$79="")) -> 3 | E21: =D21/COUNTA(Outreach_Data!$A$2:$A$79) -> 0.038461538 | F21: High | G21: Cannot measure recency or follow-up timing. | H21: Log a date for every touchpoint.
A22: 18 | B22: Status conflicts with interaction count | C22: Status vs Interactions | D22: =SUMPRODUCT((Outreach_Data!$S$2:$S$79="Not Started")*(Outreach_Data!$N$2:$N$79>0))+SUMPRODUCT((Outreach_Data!$S$2:$S$79<>"Not Started")*(Outreach_Data!$S$2:$S$79<>"Not Recorded")*(Outreach_Data!$N$2:$N$79=0)) -> 4 | E22: =D22/COUNTA(Outreach_Data!$A$2:$A$79) -> 0.051282051 | F22: Medium | G22: Either the status or the interaction log is wrong. | H22: Review and align; auto-update status from activity log.
A23: 19 | B23: Active partnership with Low/None engagement | C23: Status vs Engagement | D23: =SUMPRODUCT((Outreach_Data!$S$2:$S$79="Partnership Active")*(((Outreach_Data!$T$2:$T$79="Low")+(Outreach_Data!$T$2:$T$79="None"))>0)) -> 2 | E23: =D23/COUNTA(Outreach_Data!$A$2:$A$79) -> 0.025641026 | F23: Medium | G23: Contradiction: either at-risk partnership or wrong rating. | H23: Review with owner.
A24: 20 | B24: Next action due date missing | C24: Next Action Due | D24: =COUNTBLANK(Outreach_Data!$P$2:$P$79) -> 5 | E24: =D24/COUNTA(Outreach_Data!$A$2:$A$79) -> 0.064102564 | F24: Medium | G24: No follow-up trigger; records can silently go cold. | H24: Require a due date for every open record.
A25: 21 | B25: Outlier interaction count (>20) | C25: Interactions | D25: =COUNTIF(Outreach_Data!$N$2:$N$79,">20") -> 1 | E25: =D25/COUNTA(Outreach_Data!$A$2:$A$79) -> 0.012820513 | F25: Low | G25: Possible entry error (e.g. 48) skewing averages. | H25: Verify and correct.
A27: Summary
B28: Records in database | D28: =COUNTA(Outreach_Data!$A$2:$A$79) -> 78
B29: Records with at least one issue | D29: =COUNTIF(Outreach_Data!$Y$2:$Y$79,">0") -> 49
B30: % of records with at least one issue | D30: =COUNTIF(Outreach_Data!$Y$2:$Y$79,">0")/COUNTA(Outreach_Data!$A$2:$A$79) -> 0.62820513
B31: Total issue flags raised (row level) | D31: =SUM(Outreach_Data!$Y$2:$Y$79) -> 79
B32: Checks with at least one failing record | D32: =COUNTIF(D5:D25,">0")&" of "&ROWS(D5:D25) -> 21 of 21
A35: Observations & how they were handled in this workbook
A36: • Label variants (status, region, engagement) were standardised with the Lists sheet via formulas; the raw columns are left untouched so the original entries can be audited.
A37: • Dates stored as text are not corrected in place; they are excluded from date-based metrics (recency, overdue, monthly trend) and counted as an issue instead.
A38: • Duplicates are kept in the data; the dashboard shows both unique embassies and total records, so the duplication effect is visible.
A39: • 'Not Recorded' rows appear in the status, region and engagement tables so that totals always reconcile to the full record count.
A40: • 'Issue Count' (Outreach_Data, column Y) gives a per-record flag count; filter it to build a clean-up worklist for owners.
A41: • Data in this workbook is an illustrative sample created for the assessment because the source database was not supplied; patterns shown are not real findings.

Sheet Outreach_Data
A1: Embassy ID | B1: Embassy (Country) | C1: Region | D1: Contact Person | E1: Designation | F1: Email | G1: Phone | H1: Outreach Channel | I1: Owner | J1: First Contact Date | K1: Last Contact Date | L1: Status | M1: Engagement Level | N1: Interactions | O1: Next Action | P1: Next Action Due | Q1: Remarks | R1: Std Region | S1: Std Status | T1: Std Engagement | U1: Days Since Last Contact | V1: Overdue? (1/0) | W1: Days Overdue | X1: Stale? (1/0) | Y1: Issue Count | Z1: Priority Key | AA1: Engaged? (1/0) | AB1: Outreach Started? (1/0)
A2: EMB-001 | B2: Chile | C2: Americas | D2: Layla Silva | E2: First Secretary | F2: layla.silva@chile-embassy.example | G2: +91-11-2846-3330 | H2: Email | I2: Aisha Khan | L2: Not Started | M2: None | N2: 0 | O2: Send introductory letter | P2: 46314 | Q2: Prefers formal letters | R2: =IF(TRIM(C2)="","Not Recorded",IFERROR(INDEX(Lists!$B$2:$B$60,MATCH(TRIM(C2),Lists!$A$2:$A$60,0)),"Not Recorded")) -> Americas | S2: =IF(TRIM(L2)="","Not Recorded",IFERROR(INDEX(Lists!$E$2:$E$60,MATCH(TRIM(L2),Lists!$D$2:$D$60,0)),"Not Recorded")) -> Not Started | T2: =IF(TRIM(M2)="","Not Recorded",IFERROR(INDEX(Lists!$H$2:$H$60,MATCH(TRIM(M2),Lists!$G$2:$G$60,0)),"Not Recorded")) -> None | U2: =IF(ISNUMBER(K2),Lists!$K$2-K2,"") | V2: =IF(AND(ISNUMBER(P2),P2<Lists!$K$2,S2<>"On Hold"),1,0) -> 0 | W2: =IF(V2=1,Lists!$K$2-P2,0) -> 0 | X2: =IF(AND(ISNUMBER(K2),S2<>"On Hold"),IF(Lists!$K$2-K2>Lists!$K$3,1,0),0) -> 0 | Y2: =(F2="")+IF(F2="",0,ISERROR(FIND("@",F2))*1)+(D2="")+(I2="")+(R2="Not Recorded")+(S2="Not Recorded")+(T2="Not Recorded")+((ISTEXT(J2)+ISTEXT(K2)+ISTEXT(P2))>0)+IF(AND(ISNUMBER(J2),ISNUMBER(K2)),(K2<J2)*1,0)+IF(ISNUMBER(K2),(K2>Lists!$K$2)*1,0)+(COUNTIF($B$2:$B$79,B2)>1)+IF(S2="Not Started",(N2>0)*1,IF(S2="Not Recorded",0,(N2=0)*1))+IF(AND(S2<>"Not Started",S2<>"Not Recorded"),(K2="")*1,0)+(P2="")+(G2="")+IF(G2="",0,(LEFT(G2,1)<>"+")*1) -> 1 | Z2: =IF(V2=1,W2+ROW()/100000,0) -> 0 | AA2: =IF(OR(S2="In Discussion",S2="Meeting Scheduled",S2="Partnership Active"),1,0) -> 0 | AB2: =IF(AND(S2<>"Not Started",S2<>"Not Recorded"),1,0) -> 0
A3: EMB-002 | B3: Indonesia | C3: Asia-Pacific | E3: Commercial Counsellor | F3: fatima.lindberg@indonesia-embassy.example | G3: +91-11-2323-5272 | H3: Phone | I3: Karan Joshi | J3: 46168 | K3: 46211 | L3: No Response | M3: LOW | N3: 2 | O3: Escalate via phone / alternate contact | P3: 46240 | R3: =IF(TRIM(C3)="","Not Recorded",IFERROR(INDEX(Lists!$B$2:$B$60,MATCH(TRIM(C3),Lists!$A$2:$A$60,0)),"Not Recorded")) -> Asia-Pacific | S3: =IF(TRIM(L3)="","Not Recorded",IFERROR(INDEX(Lists!$E$2:$E$60,MATCH(TRIM(L3),Lists!$D$2:$D$60,0)),"Not Recorded")) -> No Response | T3: =IF(TRIM(M3)="","Not Recorded",IFERROR(INDEX(Lists!$H$2:$H$60,MATCH(TRIM(M3),Lists!$G$2:$G$60,0)),"Not Recorded")) -> Low | U3: =IF(ISNUMBER(K3),Lists!$K$2-K3,"") -> 90 | V3: =IF(AND(ISNUMBER(P3),P3<Lists!$K$2,S3<>"On Hold"),1,0) -> 1 | W3: =IF(V3=1,Lists!$K$2-P3,0) -> 61 | X3: =IF(AND(ISNUMBER(K3),S3<>"On Hold"),IF(Lists!$K$2-K3>Lists!$K$3,1,0),0) -> 1 | Y3: =(F3="")+IF(F3="",0,ISERROR(FIND("@",F3))*1)+(D3="")+(I3="")+(R3="Not Recorded")+(S3="Not Recorded")+(T3="Not Recorded")+((ISTEXT(J3)+ISTEXT(K3)+ISTEXT(P3))>0)+IF(AND(ISNUMBER(J3),ISNUMBER(K3)),(K3<J3)*1,0)+IF(ISNUMBER(K3),(K3>Lists!$K$2)*1,0)+(COUNTIF($B$2:$B$79,B3)>1)+IF(S3="Not Started",(N3>0)*1,IF(S3="Not Recorded",0,(N3=0)*1))+IF(AND(S3<>"Not Started",S3<>"Not Recorded"),(K3="")*1,0)+(P3="")+(G3="")+IF(G3="",0,(LEFT(G3,1)<>"+")*1) -> 1 | Z3: =IF(V3=1,W3+ROW()/100000,0) -> 61.00003 | AA3: =IF(OR(S3="In Discussion",S3="Meeting Scheduled",S3="Partnership Active"),1,0) -> 0 | AB3: =IF(AND(S3<>"Not Started",S3<>"Not Recorded"),1,0) -> 1
A4: EMB-003 | B4: Mexico | C4: Americas | D4: Grace Garcia | E4: Protocol Officer | F4: grace.garcia@mexico-embassy.example | G4: +91-11-2880-8438 | H4: Email | I4: Karan Joshi | L4: Not Started | M4: None | N4: 0 | O4: Send introductory letter | P4: 46313 | Q4: Prefers formal letters | R4: =IF(TRIM(C4)="","Not Recorded",IFERROR(INDEX(Lists!$B$2:$B$60,MATCH(TRIM(C4),Lists!$A$2:$A$60,0)),"Not Recorded")) -> Americas | S4: =IF(TRIM(L4)="","Not Recorded",IFERROR(INDEX(Lists!$E$2:$E$60,MATCH(TRIM(L4),Lists!$D$2:$D$60,0)),"Not Recorded")) -> Not Started | T4: =IF(TRIM(M4)="","Not Recorded",IFERROR(INDEX(Lists!$H$2:$H$60,MATCH(TRIM(M4),Lists!$G$2:$G$60,0)),"Not Recorded")) -> None | U4: =IF(ISNUMBER(K4),Lists!$K$2-K4,"") | V4: =IF(AND(ISNUMBER(P4),P4<Lists!$K$2,S4<>"On Hold"),1,0) -> 0 | W4: =IF(V4=1,Lists!$K$2-P4,0) -> 0 | X4: =IF(AND(ISNUMBER(K4),S4<>"On Hold"),IF(Lists!$K$2-K4>Lists!$K$3,1,0),0) -> 0 | Y4: =(F4="")+IF(F4="",0,ISERROR(FIND("@",F4))*1)+(D4="")+(I4="")+(R4="Not Recorded")+(S4="Not Recorded")+(T4="Not Recorded")+((ISTEXT(J4)+ISTEXT(K4)+ISTEXT(P4))>0)+IF(AND(ISNUMBER(J4),ISNUMBER(K4)),(K4<J4)*1,0)+IF(ISNUMBER(K4),(K4>Lists!$K$2)*1,0)+(COUNTIF($B$2:$B$79,B4)>1)+IF(S4="Not Started",(N4>0)*1,IF(S4="Not Recorded",0,(N4=0)*1))+IF(AND(S4<>"Not Started",S4<>"Not Recorded"),(K4="")*1,0)+(P4="")+(G4="")+IF(G4="",0,(LEFT(G4,1)<>"+")*1) -> 0 | Z4: =IF(V4=1,W4+ROW()/100000,0) -> 0 | AA4: =IF(OR(S4="In Discussion",S4="Meeting Scheduled",S4="Partnership Active"),1,0) -> 0 | AB4: =IF(AND(S4<>"Not Started",S4<>"Not Recorded"),1,0) -> 0
A5: EMB-004 | B5: Laos | C5: Asia-Pacific | D5: Pedro Dubois | E5: Protocol Officer | F5: pedro.dubois@laos-embassy.example | G5: +91-11-2302-3085 | H5: Phone | I5: Imran Sheikh | J5: 46201 | K5: 46288 | L5: in discussion | M5: Medium | N5: 8 | O5: Share proposal / MoU draft | P5: 46323 | Q5: Awaiting reply from HQ | R5: =IF(TRIM(C5)="","Not Recorded",IFERROR(INDEX(Lists!$B$2:$B$60,MATCH(TRIM(C5),Lists!$A$2:$A$60,0)),"Not Recorded")) -> Asia-Pacific | S5: =IF(TRIM(L5)="","Not Recorded",IFERROR(INDEX(Lists!$E$2:$E$60,MATCH(TRIM(L5),Lists!$D$2:$D$60,0)),"Not Recorded")) -> In Discussion | T5: =IF(TRIM(M5)="","Not Recorded",IFERROR(INDEX(Lists!$H$2:$H$60,MATCH(TRIM(M5),Lists!$G$2:$G$60,0)),"Not Recorded")) -> Medium | U5: =IF(ISNUMBER(K5),Lists!$K$2-K5,"") -> 13 | V5: =IF(AND(ISNUMBER(P5),P5<Lists!$K$2,S5<>"On Hold"),1,0) -> 0 | W5: =IF(V5=1,Lists!$K$2-P5,0) -> 0 | X5: =IF(AND(ISNUMBER(K5),S5<>"On Hold"),IF(Lists!$K$2-K5>Lists!$K$3,1,0),0) -> 0 | Y5: =(F5="")+IF(F5="",0,ISERROR(FIND("@",F5))*1)+(D5="")+(I5="")+(R5="Not Recorded")+(S5="Not Recorded")+(T5="Not Recorded")+((ISTEXT(J5)+ISTEXT(K5)+ISTEXT(P5))>0)+IF(AND(ISNUMBER(J5),ISNUMBER(K5)),(K5<J5)*1,0)+IF(ISNUMBER(K5),(K5>Lists!$K$2)*1,0)+(COUNTIF($B$2:$B$79,B5)>1)+IF(S5="Not Started",(N5>0)*1,IF(S5="Not Recorded",0,(N5=0)*1))+IF(AND(S5<>"Not Started",S5<>"Not Recorded"),(K5="")*1,0)+(P5="")+(G5="")+IF(G5="",0,(LEFT(G5,1)<>"+")*1) -> 0 | Z5: =IF(V5=1,W5+ROW()/100000,0) -> 0 | AA5: =IF(OR(S5="In Discussion",S5="Meeting Scheduled",S5="Partnership Active"),1,0) -> 1 | AB5: =IF(AND(S5<>"Not Started",S5<>"Not Recorded"),1,0) -> 1
A6: EMB-005 | B6: Vietnam | C6: Asia-Pacific | D6: Hiro Petrov | E6: Ambassador's Office | F6: hiro.petrov.vietnam-embassy.example | G6: +91-11-2911-2753 | H6: Letter | I6: Rohan Mehta | J6: 46148 | K6: 46338 | L6: On Hold | M6: Medium | N6: 6 | O6: Review in next quarter | Q6: Prefers formal letters | R6: =IF(TRIM(C6)="","Not Recorded",IFERROR(INDEX(Lists!$B$2:$B$60,MATCH(TRIM(C6),Lists!$A$2:$A$60,0)),"Not Recorded")) -> Asia-Pacific | S6: =IF(TRIM(L6)="","Not Recorded",IFERROR(INDEX(Lists!$E$2:$E$60,MATCH(TRIM(L6),Lists!$D$2:$D$60,0)),"Not Recorded")) -> On Hold | T6: =IF(TRIM(M6)="","Not Recorded",IFERROR(INDEX(Lists!$H$2:$H$60,MATCH(TRIM(M6),Lists!$G$2:$G$60,0)),"Not Recorded")) -> Medium | U6: =IF(ISNUMBER(K6),Lists!$K$2-K6,"") -> -37 | V6: =IF(AND(ISNUMBER(P6),P6<Lists!$K$2,S6<>"On Hold"),1,0) -> 0 | W6: =IF(V6=1,Lists!$K$2-P6,0) -> 0 | X6: =IF(AND(ISNUMBER(K6),S6<>"On Hold"),IF(Lists!$K$2-K6>Lists!$K$3,1,0),0) -> 0 | Y6: =(F6="")+IF(F6="",0,ISERROR(FIND("@",F6))*1)+(D6="")+(I6="")+(R6="Not Recorded")+(S6="Not Recorded")+(T6="Not Recorded")+((ISTEXT(J6)+ISTEXT(K6)+ISTEXT(P6))>0)+IF(AND(ISNUMBER(J6),ISNUMBER(K6)),(K6<J6)*1,0)+IF(ISNUMBER(K6),(K6>Lists!$K$2)*1,0)+(COUNTIF($B$2:$B$79,B6)>1)+IF(S6="Not Started",(N6>0)*1,IF(S6="Not Recorded",0,(N6=0)*1))+IF(AND(S6<>"Not Started",S6<>"Not Recorded"),(K6="")*1,0)+(P6="")+(G6="")+IF(G6="",0,(LEFT(G6,1)<>"+")*1) -> 3 | Z6: =IF(V6=1,W6+ROW()/100000,0) -> 0 | AA6: =IF(OR(S6="In Discussion",S6="Meeting Scheduled",S6="Partnership Active"),1,0) -> 0 | AB6: =IF(AND(S6<>"Not Started",S6<>"Not Recorded"),1,0) -> 1
A7: EMB-006 | B7: China | C7: Asia-Pacific | D7: Lucas Chen | E7: Ambassador's Office | G7: +91-11-2118-5279 | H7: Phone | I7: Neha Verma | J7: 46140 | K7: 46261 | L7: in discussion | M7: High | N7: 3 | O7: Share proposal / MoU draft | P7: 46293 | R7: =IF(TRIM(C7)="","Not Recorded",IFERROR(INDEX(Lists!$B$2:$B$60,MATCH(TRIM(C7),Lists!$A$2:$A$60,0)),"Not Recorded")) -> Asia-Pacific | S7: =IF(TRIM(L7)="","Not Recorded",IFERROR(INDEX(Lists!$E$2:$E$60,MATCH(TRIM(L7),Lists!$D$2:$D$60,0)),"Not Recorded")) -> In Discussion | T7: =IF(TRIM(M7)="","Not Recorded",IFERROR(INDEX(Lists!$H$2:$H$60,MATCH(TRIM(M7),Lists!$G$2:$G$60,0)),"Not Recorded")) -> High | U7: =IF(ISNUMBER(K7),Lists!$K$2-K7,"") -> 40 | V7: =IF(AND(ISNUMBER(P7),P7<Lists!$K$2,S7<>"On Hold"),1,0) -> 1 | W7: =IF(V7=1,Lists!$K$2-P7,0) -> 8 | X7: =IF(AND(ISNUMBER(K7),S7<>"On Hold"),IF(Lists!$K$2-K7>Lists!$K$3,1,0),0) -> 1 | Y7: =(F7="")+IF(F7="",0,ISERROR(FIND("@",F7))*1)+(D7="")+(I7="")+(R7="Not Recorded")+(S7="Not Recorded")+(T7="Not Recorded")+((ISTEXT(J7)+ISTEXT(K7)+ISTEXT(P7))>0)+IF(AND(ISNUMBER(J7),ISNUMBER(K7)),(K7<J7)*1,0)+IF(ISNUMBER(K7),(K7>Lists!$K$2)*1,0)+(COUNTIF($B$2:$B$79,B7)>1)+IF(S7="Not Started",(N7>0)*1,IF(S7="Not Recorded",0,(N7=0)*1))+IF(AND(S7<>"Not Started",S7<>"Not Recorded"),(K7="")*1,0)+(P7="")+(G7="")+IF(G7="",0,(LEFT(G7,1)<>"+")*1) -> 1 | Z7: =IF(V7=1,W7+ROW()/100000,0) -> 8.00007 | AA7: =IF(OR(S7="In Discussion",S7="Meeting Scheduled",S7="Partnership Active"),1,0) -> 1 | AB7: =IF(AND(S7<>"Not Started",S7<>"Not Recorded"),1,0) -> 1
A8: EMB-007 | B8: Colombia | C8: Americas | D8: Yusuf Chen | E8: Commercial Counsellor | F8: yusuf.chen@colombia-embassy.example | G8: +91-11-2256-1423 | H8: Email | I8: Rohan Mehta | L8: Not Started | M8: None | N8: 0 | O8: Send introductory letter | P8: 46322 | Q8: Holiday season delay | R8: =IF(TRIM(C8)="","Not Recorded",IFERROR(INDEX(Lists!$B$2:$B$60,MATCH(TRIM(C8),Lists!$A$2:$A$60,0)),"Not Recorded")) -> Americas | S8: =IF(TRIM(L8)="","Not Recorded",IFERROR(INDEX(Lists!$E$2:$E$60,MATCH(TRIM(L8),Lists!$D$2:$D$60,0)),"Not Recorded")) -> Not Started | T8: =IF(TRIM(M8)="","Not Recorded",IFERROR(INDEX(Lists!$H$2:$H$60,MATCH(TRIM(M8),Lists!$G$2:$G$60,0)),"Not Recorded")) -> None | U8: =IF(ISNUMBER(K8),Lists!$K$2-K8,"") | V8: =IF(AND(ISNUMBER(P8),P8<Lists!$K$2,S8<>"On Hold"),1,0) -> 0 | W8: =IF(V8=1,Lists!$K$2-P8,0) -> 0 | X8: =IF(AND(ISNUMBER(K8),S8<>"On Hold"),IF(Lists!$K$2-K8>Lists!$K$3,1,0),0) -> 0 | Y8: =(F8="")+IF(F8="",0,ISERROR(FIND("@",F8))*1)+(D8="")+(I8="")+(R8="Not Recorded")+(S8="Not Recorded")+(T8="Not Recorded")+((ISTEXT(J8)+ISTEXT(K8)+ISTEXT(P8))>0)+IF(AND(ISNUMBER(J8),ISNUMBER(K8)),(K8<J8)*1,0)+IF(ISNUMBER(K8),(K8>Lists!$K$2)*1,0)+(COUNTIF($B$2:$B$79,B8)>1)+IF(S8="Not Started",(N8>0)*1,IF(S8="Not Recorded",0,(N8=0)*1))+IF(AND(S8<>"Not Started",S8<>"Not Recorded"),(K8="")*1,0)+(P8="")+(G8="")+IF(G8="",0,(LEFT(G8,1)<>"+")*1) -> 0 | Z8: =IF(V8=1,W8+ROW()/100000,0) -> 0 | AA8: =IF(OR(S8="In Discussion",S8="Meeting Scheduled",S8="Partnership Active"),1,0) -> 0 | AB8: =IF(AND(S8<>"Not Started",S8<>"Not Recorded"),1,0) -> 0
A9: EMB-008 | B9: Algeria | C9: Africa | D9: Layla Park | E9: Protocol Officer | F9: layla.park@algeria-embassy.example | G9: +91-11-2197-6169 | H9: Email | I9: Karan Joshi | J9: 46283 | K9: 18-Sep-2026 | L9: Contacted | M9: Medium | N9: 1 | O9: Follow-up email | P9: 46323 | R9: =IF(TRIM(C9)="","Not Recorded",IFERROR(INDEX(Lists!$B$2:$B$60,MATCH(TRIM(C9),Lists!$A$2:$A$60,0)),"Not Recorded")) -> Africa | S9: =IF(TRIM(L9)="","Not Recorded",IFERROR(INDEX(Lists!$E$2:$E$60,MATCH(TRIM(L9),Lists!$D$2:$D$60,0)),"Not Recorded")) -> Contacted | T9: =IF(TRIM(M9)="","Not Recorded",IFERROR(INDEX(Lists!$H$2:$H$60,MATCH(TRIM(M9),Lists!$G$2:$G$60,0)),"Not Recorded")) -> Medium | U9: =IF(ISNUMBER(K9),Lists!$K$2-K9,"") | V9: =IF(AND(ISNUMBER(P9),P9<Lists!$K$2,S9<>"On Hold"),1,0) -> 0 | W9: =IF(V9=1,Lists!$K$2-P9,0) -> 0 | X9: =IF(AND(ISNUMBER(K9),S9<>"On Hold"),IF(Lists!$K$2-K9>Lists!$K$3,1,0),0) -> 0 | Y9: =(F9="")+IF(F9="",0,ISERROR(FIND("@",F9))*1)+(D9="")+(I9="")+(R9="Not Recorded")+(S9="Not Recorded")+(T9="Not Recorded")+((ISTEXT(J9)+ISTEXT(K9)+ISTEXT(P9))>0)+IF(AND(ISNUMBER(J9),ISNUMBER(K9)),(K9<J9)*1,0)+IF(ISNUMBER(K9),(K9>Lists!$K$2)*1,0)+(COUNTIF($B$2:$B$79,B9)>1)+IF(S9="Not Started",(N9>0)*1,IF(S9="Not Recorded",0,(N9=0)*1))+IF(AND(S9<>"Not Started",S9<>"Not Recorded"),(K9="")*1,0)+(P9="")+(G9="")+IF(G9="",0,(LEFT(G9,1)<>"+")*1) -> 1 | Z9: =IF(V9=1,W9+ROW()/100000,0) -> 0 | AA9: =IF(OR(S9="In Discussion",S9="Meeting Scheduled",S9="Partnership Active"),1,0) -> 0 | AB9: =IF(AND(S9<>"Not Started",S9<>"Not Recorded"),1,0) -> 1
A10: EMB-009 | B10: Jordan | C10: Middle East | D10: Fatima Rossi | E10: Political Counsellor | F10: fatima.rossi@jordan-embassy.example | G10: +91-11-2901-7232 | H10: Event | I10: Aisha Khan | J10: 46159 | K10: 46276 | L10: Partnership Active | M10: None | N10: 20 | O10: Quarterly review call | P10: 46320 | Q10: Prefers formal letters | R10: =IF(TRIM(C10)="","Not Recorded",IFERROR(INDEX(Lists!$B$2:$B$60,MATCH(TRIM(C10),Lists!$A$2:$A$60,0)),"Not Recorded")) -> Middle East | S10: =IF(TRIM(L10)="","Not Recorded",IFERROR(INDEX(Lists!$E$2:$E$60,MATCH(TRIM(L10),Lists!$D$2:$D$60,0)),"Not Recorded")) -> Partnership Active | T10: =IF(TRIM(M10)="","Not Recorded",IFERROR(INDEX(Lists!$H$2:$H$60,MATCH(TRIM(M10),Lists!$G$2:$G$60,0)),"Not Recorded")) -> None | U10: =IF(ISNUMBER(K10),Lists!$K$2-K10,"") -> 25 | V10: =IF(AND(ISNUMBER(P10),P10<Lists!$K$2,S10<>"On Hold"),1,0) -> 0 | W10: =IF(V10=1,Lists!$K$2-P10,0) -> 0 | X10: =IF(AND(ISNUMBER(K10),S10<>"On Hold"),IF(Lists!$K$2-K10>Lists!$K$3,1,0),0) -> 0 | Y10: =(F10="")+IF(F10="",0,ISERROR(FIND("@",F10))*1)+(D10="")+(I10="")+(R10="Not Recorded")+(S10="Not Recorded")+(T10="Not Recorded")+((ISTEXT(J10)+ISTEXT(K10)+ISTEXT(P10))>0)+IF(AND(ISNUMBER(J10),ISNUMBER(K10)),(K10<J10)*1,0)+IF(ISNUMBER(K10),(K10>Lists!$K$2)*1,0)+(COUNTIF($B$2:$B$79,B10)>1)+IF(S10="Not Started",(N10>0)*1,IF(S10="Not Recorded",0,(N10=0)*1))+IF(AND(S10<>"Not Started",S10<>"Not Recorded"),(K10="")*1,0)+(P10="")+(G10="")+IF(G10="",0,(LEFT(G10,1)<>"+")*1) -> 0 | Z10: =IF(V10=1,W10+ROW()/100000,0) -> 0 | AA10: =IF(OR(S10="In Discussion",S10="Meeting Scheduled",S10="Partnership Active"),1,0) -> 1 | AB10: =IF(AND(S10<>"Not Started",S10<>"Not Recorded"),1,0) -> 1
A11: EMB-010 | B11: South Korea | C11: Asia-pacific | D11: Kwame Fernandez | E11: Protocol Officer | F11: kwame.fernandez@southkorea-embassy.example | G11: +91-11-2735-8973 | H11: Phone | I11: Rohan Mehta | J11: 46187 | K11: 46187 | L11: No Response | M11: Low | N11: 1 | O11: Escalate via phone / alternate contact | P11: 46231 | R11: =IF(TRIM(C11)="","Not Recorded",IFERROR(INDEX(Lists!$B$2:$B$60,MATCH(TRIM(C11),Lists!$A$2:$A$60,0)),"Not Recorded")) -> Asia-Pacific | S11: =IF(TRIM(L11)="","Not Recorded",IFERROR(INDEX(Lists!$E$2:$E$60,MATCH(TRIM(L11),Lists!$D$2:$D$60,0)),"Not Recorded")) -> No Response | T11: =IF(TRIM(M11)="","Not Recorded",IFERROR(INDEX(Lists!$H$2:$H$60,MATCH(TRIM(M11),Lists!$G$2:$G$60,0)),"Not Recorded")) -> Low | U11: =IF(ISNUMBER(K11),Lists!$K$2-K11,"") -> 114 | V11: =IF(AND(ISNUMBER(P11),P11<Lists!$K$2,S11<>"On Hold"),1,0) -> 1 | W11: =IF(V11=1,Lists!$K$2-P11,0) -> 70 | X11: =IF(AND(ISNUMBER(K11),S11<>"On Hold"),IF(Lists!$K$2-K11>Lists!$K$3,1,0),0) -> 1 | Y11: =(F11="")+IF(F11="",0,ISERROR(FIND("@",F11))*1)+(D11="")+(I11="")+(R11="Not Recorded")+(S11="Not Recorded")+(T11="Not Recorded")+((ISTEXT(J11)+ISTEXT(K11)+ISTEXT(P11))>0)+IF(AND(ISNUMBER(J11),ISNUMBER(K11)),(K11<J11)*1,0)+IF(ISNUMBER(K11),(K11>Lists!$K$2)*1,0)+(COUNTIF($B$2:$B$79,B11)>1)+IF(S11="Not Started",(N11>0)*1,IF(S11="Not Recorded",0,(N11=0)*1))+IF(AND(S11<>"Not Started",S11<>"Not Recorded"),(K11="")*1,0)+(P11="")+(G11="")+IF(G11="",0,(LEFT(G11,1)<>"+")*1) -> 0 | Z11: =IF(V11=1,W11+ROW()/100000,0) -> 70.00011 | AA11: =IF(OR(S11="In Discussion",S11="Meeting Scheduled",S11="Partnership Active"),1,0) -> 0 | AB11: =IF(AND(S11<>"Not Started",S11<>"Not Recorded"),1,0) -> 1
A12: EMB-011 | B12: Bangladesh | C12: Asia-pacific | D12: Fatima Fernandez | E12: Cultural Attaché | F12: fatima.fernandez@bangladesh-embassy.example | G12: +91-11-2440-3088 | H12: Email | I12: Priya Nair | J12: 46214 | K12: 46287 | L12: Partnership Active | M12: High | N12: 13 | O12: Quarterly review call | P12: 46303 | R12: =IF(TRIM(C12)="","Not Recorded",IFERROR(INDEX(Lists!$B$2:$B$60,MATCH(TRIM(C12),Lists!$A$2:$A$60,0)),"Not Recorded")) -> Asia-Pacific | S12: =IF(TRIM(L12)="","Not Recorded",IFERROR(INDEX(Lists!$E$2:$E$60,MATCH(TRIM(L12),Lists!$D$2:$D$60,0)),"Not Recorded")) -> Partnership Active | T12: =IF(TRIM(M12)="","Not Recorded",IFERROR(INDEX(Lists!$H$2:$H$60,MATCH(TRIM(M12),Lists!$G$2:$G$60,0)),"Not Recorded")) -> High | U12: =IF(ISNUMBER(K12),Lists!$K$2-K12,"") -> 14 | V12: =IF(AND(ISNUMBER(P12),P12<Lists!$K$2,S12<>"On Hold"),1,0) -> 0 | W12: =IF(V12=1,Lists!$K$2-P12,0) -> 0 | X12: =IF(AND(ISNUMBER(K12),S12<>"On Hold"),IF(Lists!$K$2-K12>Lists!$K$3,1,0),0) -> 0 | Y12: =(F12="")+IF(F12="",0,ISERROR(FIND("@",F12))*1)+(D12="")+(I12="")+(R12="Not Recorded")+(S12="Not Recorded")+(T12="Not Recorded")+((ISTEXT(J12)+ISTEXT(K12)+ISTEXT(P12))>0)+IF(AND(ISNUMBER(J12),ISNUMBER(K12)),(K12<J12)*1,0)+IF(ISNUMBER(K12),(K12>Lists!$K$2)*1,0)+(COUNTIF($B$2:$B$79,B12)>1)+IF(S12="Not Started",(N12>0)*1,IF(S12="Not Recorded",0,(N12=0)*1))+IF(AND(S12<>"Not Started",S12<>"Not Recorded"),(K12="")*1,0)+(P12="")+(G12="")+IF(G12="",0,(LEFT(G12,1)<>"+")*1) -> 0 | Z12: =IF(V12=1,W12+ROW()/100000,0) -> 0 | AA12: =IF(OR(S12="In Discussion",S12="Meeting Scheduled",S12="Partnership Active"),1,0) -> 1 | AB12: =IF(AND(S12<>"Not Started",S12<>"Not Recorded"),1,0) -> 1
A13: EMB-012 | B13: Switzerland | C13: Europe | D13: Mina Mensah | E13: Press Officer | F13: mina.mensah@switzerland-embassy.example | G13: +91-11-2276-4598 | H13: Meeting | I13: Aisha Khan | J13: 46210 | K13: 46194 | L13: Meeting Scheduled | M13: Medium | N13: 6 | O13: Prepare meeting brief | R13: =IF(TRIM(C13)="","Not Recorded",IFERROR(INDEX(Lists!$B$2:$B$60,MATCH(TRIM(C13),Lists!$A$2:$A$60,0)),"Not Recorded")) -> Europe | S13: =IF(TRIM(L13)="","Not Recorded",IFERROR(INDEX(Lists!$E$2:$E$60,MATCH(TRIM(L13),Lists!$D$2:$D$60,0)),"Not Recorded")) -> Meeting Scheduled | T13: =IF(TRIM(M13)="","Not Recorded",IFERROR(INDEX(Lists!$H$2:$H$60,MATCH(TRIM(M13),Lists!$G$2:$G$60,0)),"Not Recorded")) -> Medium | U13: =IF(ISNUMBER(K13),Lists!$K$2-K13,"") -> 107 | V13: =IF(AND(ISNUMBER(P13),P13<Lists!$K$2,S13<>"On Hold"),1,0) -> 0 | W13: =IF(V13=1,Lists!$K$2-P13,0) -> 0 | X13: =IF(AND(ISNUMBER(K13),S13<>"On Hold"),IF(Lists!$K$2-K13>Lists!$K$3,1,0),0) -> 1 | Y13: =(F13="")+IF(F13="",0,ISERROR(FIND("@",F13))*1)+(D13="")+(I13="")+(R13="Not Recorded")+(S13="Not Recorded")+(T13="Not Recorded")+((ISTEXT(J13)+ISTEXT(K13)+ISTEXT(P13))>0)+IF(AND(ISNUMBER(J13),ISNUMBER(K13)),(K13<J13)*1,0)+IF(ISNUMBER(K13),(K13>Lists!$K$2)*1,0)+(COUNTIF($B$2:$B$79,B13)>1)+IF(S13="Not Started",(N13>0)*1,IF(S13="Not Recorded",0,(N13=0)*1))+IF(AND(S13<>"Not Started",S13<>"Not Recorded"),(K13="")*1,0)+(P13="")+(G13="")+IF(G13="",0,(LEFT(G13,1)<>"+")*1) -> 2 | Z13: =IF(V13=1,W13+ROW()/100000,0) -> 0 | AA13: =IF(OR(S13="In Discussion",S13="Meeting Scheduled",S13="Partnership Active"),1,0) -> 1 | AB13: =IF(AND(S13<>"Not Started",S13<>"Not Recorded"),1,0) -> 1
A14: EMB-013 | B14: Italy | C14: Europe | D14: Anna Haddad | E14: Protocol Officer | F14: anna.haddad@italy-embassy.example | G14: +91-11-2432-6574 | H14: Meeting | J14: 46291 | K14: 46291 | L14: Contacted | M14: Low | N14: 1 | O14: Follow-up email | P14: 46325 | Q14: Contact changed recently | R14: =IF(TRIM(C14)="","Not Recorded",IFERROR(INDEX(Lists!$B$2:$B$60,MATCH(TRIM(C14),Lists!$A$2:$A$60,0)),"Not Recorded")) -> Europe | S14: =IF(TRIM(L14)="","Not Recorded",IFERROR(INDEX(Lists!$E$2:$E$60,MATCH(TRIM(L14),Lists!$D$2:$D$60,0)),"Not Recorded")) -> Contacted | T14: =IF(TRIM(M14)="","Not Recorded",IFERROR(INDEX(Lists!$H$2:$H$60,MATCH(TRIM(M14),Lists!$G$2:$G$60,0)),"Not Recorded")) -> Low | U14: =IF(ISNUMBER(K14),Lists!$K$2-K14,"") -> 10 | V14: =IF(AND(ISNUMBER(P14),P14<Lists!$K$2,S14<>"On Hold"),1,0) -> 0 | W14: =IF(V14=1,Lists!$K$2-P14,0) -> 0 | X14: =IF(AND(ISNUMBER(K14),S14<>"On Hold"),IF(Lists!$K$2-K14>Lists!$K$3,1,0),0) -> 0 | Y14: =(F14="")+IF(F14="",0,ISERROR(FIND("@",F14))*1)+(D14="")+(I14="")+(R14="Not Recorded")+(S14="Not Recorded")+(T14="Not Recorded")+((ISTEXT(J14)+ISTEXT(K14)+ISTEXT(P14))>0)+IF(AND(ISNUMBER(J14),ISNUMBER(K14)),(K14<J14)*1,0)+IF(ISNUMBER(K14),(K14>Lists!$K$2)*1,0)+(COUNTIF($B$2:$B$79,B14)>1)+IF(S14="Not Started",(N14>0)*1,IF(S14="Not Recorded",0,(N14=0)*1))+IF(AND(S14<>"Not Started",S14<>"Not Recorded"),(K14="")*1,0)+(P14="")+(G14="")+IF(G14="",0,(LEFT(G14,1)<>"+")*1) -> 1 | Z14: =IF(V14=1,W14+ROW()/100000,0) -> 0 | AA14: =IF(OR(S14="In Discussion",S14="Meeting Scheduled",S14="Partnership Active"),1,0) -> 0 | AB14: =IF(AND(S14<>"Not Started",S14<>"Not Recorded"),1,0) -> 1
A15: EMB-014 | B15: Cambodia | D15: Lucas Nkosi | E15: First Secretary | F15: lucas.nkosi@cambodia-embassy.example | G15: +91-11-2441-2146 | H15: Meeting | I15: Neha Verma | J15: 46141 | K15: 46280 | L15: In Discussion | M15: High | N15: 3 | O15: Share proposal / MoU draft | P15: 46309 | Q15: Holiday season delay | R15: =IF(TRIM(C15)="","Not Recorded",IFERROR(INDEX(Lists!$B$2:$B$60,MATCH(TRIM(C15),Lists!$A$2:$A$60,0)),"Not Recorded")) -> Not Recorded | S15: =IF(TRIM(L15)="","Not Recorded",IFERROR(INDEX(Lists!$E$2:$E$60,MATCH(TRIM(L15),Lists!$D$2:$D$60,0)),"Not Recorded")) -> In Discussion | T15: =IF(TRIM(M15)="","Not Recorded",IFERROR(INDEX(Lists!$H$2:$H$60,MATCH(TRIM(M15),Lists!$G$2:$G$60,0)),"Not Recorded")) -> High | U15: =IF(ISNUMBER(K15),Lists!$K$2-K15,"") -> 21 | V15: =IF(AND(ISNUMBER(P15),P15<Lists!$K$2,S15<>"On Hold"),1,0) -> 0 | W15: =IF(V15=1,Lists!$K$2-P15,0) -> 0 | X15: =IF(AND(ISNUMBER(K15),S15<>"On Hold"),IF(Lists!$K$2-K15>Lists!$K$3,1,0),0) -> 0 | Y15: =(F15="")+IF(F15="",0,ISERROR(FIND("@",F15))*1)+(D15="")+(I15="")+(R15="Not Recorded")+(S15="Not Recorded")+(T15="Not Recorded")+((ISTEXT(J15)+ISTEXT(K15)+ISTEXT(P15))>0)+IF(AND(ISNUMBER(J15),ISNUMBER(K15)),(K15<J15)*1,0)+IF(ISNUMBER(K15),(K15>Lists!$K$2)*1,0)+(COUNTIF($B$2:$B$79,B15)>1)+IF(S15="Not Started",(N15>0)*1,IF(S15="Not Recorded",0,(N15=0)*1))+IF(AND(S15<>"Not Started",S15<>"Not Recorded"),(K15="")*1,0)+(P15="")+(G15="")+IF(G15="",0,(LEFT(G15,1)<>"+")*1) -> 1 | Z15: =IF(V15=1,W15+ROW()/100000,0) -> 0 | AA15: =IF(OR(S15="In Discussion",S15="Meeting Scheduled",S15="Partnership Active"),1,0) -> 1 | AB15: =IF(AND(S15<>"Not Started",S15<>"Not Recorded"),1,0) -> 1
A16: EMB-015 | B16: Malaysia | C16: Asia-Pacific | D16: Liam Rossi | E16: Press Officer | F16: liam.rossi@malaysia-embassy.example | G16: +91-11-2636-2638 | H16: Email | I16: Neha Verma | J16: 46146 | K16: 46245 | L16: No Response | M16: None | N16: 2 | O16: Escalate via phone / alternate contact | P16: 46259 | Q16: Requested brochure | R16: =IF(TRIM(C16)="","Not Recorded",IFERROR(INDEX(Lists!$B$2:$B$60,MATCH(TRIM(C16),Lists!$A$2:$A$60,0)),"Not Recorded")) -> Asia-Pacific | S16: =IF(TRIM(L16)="","Not Recorded",IFERROR(INDEX(Lists!$E$2:$E$60,MATCH(TRIM(L16),Lists!$D$2:$D$60,0)),"Not Recorded")) -> No Response | T16: =IF(TRIM(M16)="","Not Recorded",IFERROR(INDEX(Lists!$H$2:$H$60,MATCH(TRIM(M16),Lists!$G$2:$G$60,0)),"Not Recorded")) -> None | U16: =IF(ISNUMBER(K16),Lists!$K$2-K16,"") -> 56 | V16: =IF(AND(ISNUMBER(P16),P16<Lists!$K$2,S16<>"On Hold"),1,0) -> 1 | W16: =IF(V16=1,Lists!$K$2-P16,0) -> 42 | X16: =IF(AND(ISNUMBER(K16),S16<>"On Hold"),IF(Lists!$K$2-K16>Lists!$K$3,1,0),0) -> 1 | Y16: =(F16="")+IF(F16="",0,ISERROR(FIND("@",F16))*1)+(D16="")+(I16="")+(R16="Not Recorded")+(S16="Not Recorded")+(T16="Not Recorded")+((ISTEXT(J16)+ISTEXT(K16)+ISTEXT(P16))>0)+IF(AND(ISNUMBER(J16),ISNUMBER(K16)),(K16<J16)*1,0)+IF(ISNUMBER(K16),(K16>Lists!$K$2)*1,0)+(COUNTIF($B$2:$B$79,B16)>1)+IF(S16="Not Started",(N16>0)*1,IF(S16="Not Recorded",0,(N16=0)*1))+IF(AND(S16<>"Not Started",S16<>"Not Recorded"),(K16="")*1,0)+(P16="")+(G16="")+IF(G16="",0,(LEFT(G16,1)<>"+")*1) -> 0 | Z16: =IF(V16=1,W16+ROW()/100000,0) -> 42.00016 | AA16: =IF(OR(S16="In Discussion",S16="Meeting Scheduled",S16="Partnership Active"),1,0) -> 0 | AB16: =IF(AND(S16<>"Not Started",S16<>"Not Recorded"),1,0) -> 1
A17: EMB-016 | B17: Kuwait | C17: Middle East | D17: Sofia Mensah | E17: Cultural Attaché | F17: sofia.mensah@kuwait-embassy.example | G17: +91-11-2820-8612 | H17: Letter | I17: Neha Verma | J17: 46148 | K17: 46267 | L17: In Discussion | M17: Medium | N17: 6 | O17: Share proposal / MoU draft | P17: 46312 | Q17: Contact changed recently | R17: =IF(TRIM(C17)="","Not Recorded",IFERROR(INDEX(Lists!$B$2:$B$60,MATCH(TRIM(C17),Lists!$A$2:$A$60,0)),"Not Recorded")) -> Middle East | S17: =IF(TRIM(L17)="","Not Recorded",IFERROR(INDEX(Lists!$E$2:$E$60,MATCH(TRIM(L17),Lists!$D$2:$D$60,0)),"Not Recorded")) -> In Discussion | T17: =IF(TRIM(M17)="","Not Recorded",IFERROR(INDEX(Lists!$H$2:$H$60,MATCH(TRIM(M17),Lists!$G$2:$G$60,0)),"Not Recorded")) -> Medium | U17: =IF(ISNUMBER(K17),Lists!$K$2-K17,"") -> 34 | V17: =IF(AND(ISNUMBER(P17),P17<Lists!$K$2,S17<>"On Hold"),1,0) -> 0 | W17: =IF(V17=1,Lists!$K$2-P17,0) -> 0 | X17: =IF(AND(ISNUMBER(K17),S17<>"On Hold"),IF(Lists!$K$2-K17>Lists!$K$3,1,0),0) -> 1 | Y17: =(F17="")+IF(F17="",0,ISERROR(FIND("@",F17))*1)+(D17="")+(I17="")+(R17="Not Recorded")+(S17="Not Recorded")+(T17="Not Recorded")+((ISTEXT(J17)+ISTEXT(K17)+ISTEXT(P17))>0)+IF(AND(ISNUMBER(J17),ISNUMBER(K17)),(K17<J17)*1,0)+IF(ISNUMBER(K17),(K17>Lists!$K$2)*1,0)+(COUNTIF($B$2:$B$79,B17)>1)+IF(S17="Not Started",(N17>0)*1,IF(S17="Not Recorded",0,(N17=0)*1))+IF(AND(S17<>"Not Started",S17<>"Not Recorded"),(K17="")*1,0)+(P17="")+(G17="")+IF(G17="",0,(LEFT(G17,1)<>"+")*1) -> 0 | Z17: =IF(V17=1,W17+ROW()/100000,0) -> 0 | AA17: =IF(OR(S17="In Discussion",S17="Meeting Scheduled",S17="Partnership Active"),1,0) -> 1 | AB17: =IF(AND(S17<>"Not Started",S17<>"Not Recorded"),1,0) -> 1
A18: EMB-017 | B18: Lebanon | C18: Middle East | D18: Mina Müller | E18: First Secretary | F18: mina.müller@lebanon-embassy.example | H18: Phone | J18: 46195 | K18: 46276 | L18: Partnership Active | M18: High | N18: 20 | O18: Quarterly review call | Q18: Contact changed recently | R18: =IF(TRIM(C18)="","Not Recorded",IFERROR(INDEX(Lists!$B$2:$B$60,MATCH(TRIM(C18),Lists!$A$2:$A$60,0)),"Not Recorded")) -> Middle East | S18: =IF(TRIM(L18)="","Not Recorded",IFERROR(INDEX(Lists!$E$2:$E$60,MATCH(TRIM(L18),Lists!$D$2:$D$60,0)),"Not Recorded")) -> Partnership Active | T18: =IF(TRIM(M18)="","Not Recorded",IFERROR(INDEX(Lists!$H$2:$H$60,MATCH(TRIM(M18),Lists!$G$2:$G$60,0)),"Not Recorded")) -> High | U18: =IF(ISNUMBER(K18),Lists!$K$2-K18,"") -> 25 | V18: =IF(AND(ISNUMBER(P18),P18<Lists!$K$2,S18<>"On Hold"),1,0) -> 0 | W18: =IF(V18=1,Lists!$K$2-P18,0) -> 0 | X18: =IF(AND(ISNUMBER(K18),S18<>"On Hold"),IF(Lists!$K$2-K18>Lists!$K$3,1,0),0) -> 0 | Y18: =(F18="")+IF(F18="",0,ISERROR(FIND("@",F18))*1)+(D18="")+(I18="")+(R18="Not Recorded")+(S18="Not Recorded")+(T18="Not Recorded")+((ISTEXT(J18)+ISTEXT(K18)+ISTEXT(P18))>0)+IF(AND(ISNUMBER(J18),ISNUMBER(K18)),(K18<J18)*1,0)+IF(ISNUMBER(K18),(K18>Lists!$K$2)*1,0)+(COUNTIF($B$2:$B$79,B18)>1)+IF(S18="Not Started",(N18>0)*1,IF(S18="Not Recorded",0,(N18=0)*1))+IF(AND(S18<>"Not Started",S18<>"Not Recorded"),(K18="")*1,0)+(P18="")+(G18="")+IF(G18="",0,(LEFT(G18,1)<>"+")*1) -> 3 | Z18: =IF(V18=1,W18+ROW()/100000,0) -> 0 | AA18: =IF(OR(S18="In Discussion",S18="Meeting Scheduled",S18="Partnership Active"),1,0) -> 1 | AB18: =IF(AND(S18<>"Not Started",S18<>"Not Recorded"),1,0) -> 1
A19: EMB-018 | B19: Cuba | C19: Americas | D19: Mina Ali | E19: Commercial Counsellor | F19: mina.ali@cuba-embassy.example | G19: +91-11-2667-8245 | H19: Meeting | I19: Rohan Mehta | L19: Not Started | M19: None | N19: 1 | O19: Send introductory letter | P19: 46291 | Q19: Holiday season delay | R19: =IF(TRIM(C19)="","Not Recorded",IFERROR(INDEX(Lists!$B$2:$B$60,MATCH(TRIM(C19),Lists!$A$2:$A$60,0)),"Not Recorded")) -> Americas | S19: =IF(TRIM(L19)="","Not Recorded",IFERROR(INDEX(Lists!$E$2:$E$60,MATCH(TRIM(L19),Lists!$D$2:$D$60,0)),"Not Recorded")) -> Not Started | T19: =IF(TRIM(M19)="","Not Recorded",IFERROR(INDEX(Lists!$H$2:$H$60,MATCH(TRIM(M19),Lists!$G$2:$G$60,0)),"Not Recorded")) -> None | U19: =IF(ISNUMBER(K19),Lists!$K$2-K19,"") | V19: =IF(AND(ISNUMBER(P19),P19<Lists!$K$2,S19<>"On Hold"),1,0) -> 1 | W19: =IF(V19=1,Lists!$K$2-P19,0) -> 10 | X19: =IF(AND(ISNUMBER(K19),S19<>"On Hold"),IF(Lists!$K$2-K19>Lists!$K$3,1,0),0) -> 0 | Y19: =(F19="")+IF(F19="",0,ISERROR(FIND("@",F19))*1)+(D19="")+(I19="")+(R19="Not Recorded")+(S19="Not Recorded")+(T19="Not Recorded")+((ISTEXT(J19)+ISTEXT(K19)+ISTEXT(P19))>0)+IF(AND(ISNUMBER(J19),ISNUMBER(K19)),(K19<J19)*1,0)+IF(ISNUMBER(K19),(K19>Lists!$K$2)*1,0)+(COUNTIF($B$2:$B$79,B19)>1)+IF(S19="Not Started",(N19>0)*1,IF(S19="Not Recorded",0,(N19=0)*1))+IF(AND(S19<>"Not Started",S19<>"Not Recorded"),(K19="")*1,0)+(P19="")+(G19="")+IF(G19="",0,(LEFT(G19,1)<>"+")*1) -> 1 | Z19: =IF(V19=1,W19+ROW()/100000,0) -> 10.00019 | AA19: =IF(OR(S19="In Discussion",S19="Meeting Scheduled",S19="Partnership Active"),1,0) -> 0 | AB19: =IF(AND(S19<>"Not Started",S19<>"Not Recorded"),1,0) -> 0
